<?xml version="1.0"?>
<robot name="simple_drone">
  
  <!-- Main Body/Frame -->
  <link name="base_link">
    <visual>
      <geometry>
        <box size="0.3 0.3 0.08"/>
      </geometry>
      <material name="Black">
        <color rgba="0.1 0.1 0.1 1.0"/>
      </material>
    </visual>
    <collision>
      <geometry>
        <box size="0.3 0.3 0.08"/>
      </geometry>
    </collision>
    <inertial>
      <mass value="1.5"/>
      <origin xyz="0 0 0" rpy="0 0 0"/>
      <inertia ixx="0.0347" ixy="0.0" ixz="0.0" 
               iyy="0.0347" iyz="0.0" 
               izz="0.0675"/>
    </inertial>
  </link>
  
  <!-- Front Right Arm -->
  <link name="arm_front_right">
    <visual>
      <geometry>
        <box size="0.35 0.03 0.02"/>
      </geometry>
      <material name="DarkGray">
        <color rgba="0.3 0.3 0.3 1.0"/>
      </material>
    </visual>
    <collision>
      <geometry>
        <box size="0.35 0.03 0.02"/>
      </geometry>
    </collision>
    <inertial>
      <mass value="0.05"/>
      <inertia ixx="0.0001" ixy="0.0" ixz="0.0" 
               iyy="0.0005" iyz="0.0" 
               izz="0.0005"/>
    </inertial>
  </link>
  
  <joint name="arm_front_right_joint" type="fixed">
    <parent link="base_link"/>
    <child link="arm_front_right"/>
    <origin xyz="0.0875 0.0875 0.0" rpy="0 0 0.785398"/>
  </joint>
  
  <!-- Front Left Arm -->
  <link name="arm_front_left">
    <visual>
      <geometry>
        <box size="0.35 0.03 0.02"/>
      </geometry>
      <material name="DarkGray">
        <color rgba="0.3 0.3 0.3 1.0"/>
      </material>
    </visual>
    <collision>
      <geometry>
        <box size="0.35 0.03 0.02"/>
      </geometry>
    </collision>
    <inertial>
      <mass value="0.05"/>
      <inertia ixx="0.0001" ixy="0.0" ixz="0.0" 
               iyy="0.0005" iyz="0.0" 
               izz="0.0005"/>
    </inertial>
  </link>
  
  <joint name="arm_front_left_joint" type="fixed">
    <parent link="base_link"/>
    <child link="arm_front_left"/>
    <origin xyz="-0.0875 0.0875 0.0" rpy="0 0 2.356194"/>
  </joint>
  
  <!-- Rear Right Arm -->
  <link name="arm_rear_right">
    <visual>
      <geometry>
        <box size="0.35 0.03 0.02"/>
      </geometry>
      <material name="DarkGray">
        <color rgba="0.3 0.3 0.3 1.0"/>
      </material>
    </visual>
    <collision>
      <geometry>
        <box size="0.35 0.03 0.02"/>
      </geometry>
    </collision>
    <inertial>
      <mass value="0.05"/>
      <inertia ixx="0.0001" ixy="0.0" ixz="0.0" 
               iyy="0.0005" iyz="0.0" 
               izz="0.0005"/>
    </inertial>
  </link>
  
  <joint name="arm_rear_right_joint" type="fixed">
    <parent link="base_link"/>
    <child link="arm_rear_right"/>
    <origin xyz="0.0875 -0.0875 0.0" rpy="0 0 -0.785398"/>
  </joint>
  
  <!-- Rear Left Arm -->
  <link name="arm_rear_left">
    <visual>
      <geometry>
        <box size="0.35 0.03 0.02"/>
      </geometry>
      <material name="DarkGray">
        <color rgba="0.3 0.3 0.3 1.0"/>
      </material>
    </visual>
    <collision>
      <geometry>
        <box size="0.35 0.03 0.02"/>
      </geometry>
    </collision>
    <inertial>
      <mass value="0.05"/>
      <inertia ixx="0.0001" ixy="0.0" ixz="0.0" 
               iyy="0.0005" iyz="0.0" 
               izz="0.0005"/>
    </inertial>
  </link>
  
  <joint name="arm_rear_left_joint" type="fixed">
    <parent link="base_link"/>
    <child link="arm_rear_left"/>
    <origin xyz="-0.0875 -0.0875 0.0" rpy="0 0 -2.356194"/>
  </joint>
  
  <!-- Front Right Rotor -->
  <link name="rotor_front_right">
    <visual>
      <geometry>
        <cylinder radius="0.15" length="0.01"/>
      </geometry>
      <material name="Red">
        <color rgba="1.0 0.0 0.0 0.7"/>
      </material>
    </visual>
    <collision>
      <geometry>
        <cylinder radius="0.15" length="0.01"/>
      </geometry>
    </collision>
    <inertial>
      <mass value="0.02"/>
      <inertia ixx="0.0001" ixy="0.0" ixz="0.0" 
               iyy="0.0001" iyz="0.0" 
               izz="0.0002"/>
    </inertial>
  </link>
  
  <joint name="rotor_front_right_joint" type="continuous">
    <parent link="arm_front_right"/>
    <child link="rotor_front_right"/>
    <origin xyz="0.15 0.0 0.03" rpy="0 0 0"/>
    <axis xyz="0 0 1"/>
  </joint>
  
  <!-- Front Left Rotor -->
  <link name="rotor_front_left">
    <visual>
      <geometry>
        <cylinder radius="0.15" length="0.01"/>
      </geometry>
      <material name="Blue">
        <color rgba="0.0 0.0 1.0 0.7"/>
      </material>
    </visual>
    <collision>
      <geometry>
        <cylinder radius="0.15" length="0.01"/>
      </geometry>
    </collision>
    <inertial>
      <mass value="0.02"/>
      <inertia ixx="0.0001" ixy="0.0" ixz="0.0" 
               iyy="0.0001" iyz="0.0" 
               izz="0.0002"/>
    </inertial>
  </link>
  
  <joint name="rotor_front_left_joint" type="continuous">
    <parent link="arm_front_left"/>
    <child link="rotor_front_left"/>
    <origin xyz="0.15 0.0 0.03" rpy="0 0 0"/>
    <axis xyz="0 0 1"/>
  </joint>
  
  <!-- Rear Right Rotor -->
  <link name="rotor_rear_right">
    <visual>
      <geometry>
        <cylinder radius="0.15" length="0.01"/>
      </geometry>
      <material name="Blue">
        <color rgba="0.0 0.0 1.0 0.7"/>
      </material>
    </visual>
    <collision>
      <geometry>
        <cylinder radius="0.15" length="0.01"/>
      </geometry>
    </collision>
    <inertial>
      <mass value="0.02"/>
      <inertia ixx="0.0001" ixy="0.0" ixz="0.0" 
               iyy="0.0001" iyz="0.0" 
               izz="0.0002"/>
    </inertial>
  </link>
  
  <joint name="rotor_rear_right_joint" type="continuous">
    <parent link="arm_rear_right"/>
    <child link="rotor_rear_right"/>
    <origin xyz="0.15 0.0 0.03" rpy="0 0 0"/>
    <axis xyz="0 0 1"/>
  </joint>
  
  <!-- Rear Left Rotor -->
  <link name="rotor_rear_left">
    <visual>
      <geometry>
        <cylinder radius="0.15" length="0.01"/>
      </geometry>
      <material name="Red">
        <color rgba="1.0 0.0 0.0 0.7"/>
      </material>
    </visual>
    <collision>
      <geometry>
        <cylinder radius="0.15" length="0.01"/>
      </geometry>
    </collision>
    <inertial>
      <mass value="0.02"/>
      <inertia ixx="0.0001" ixy="0.0" ixz="0.0" 
               iyy="0.0001" iyz="0.0" 
               izz="0.0002"/>
    </inertial>
  </link>
  
  <joint name="rotor_rear_left_joint" type="continuous">
    <parent link="arm_rear_left"/>
    <child link="rotor_rear_left"/>
    <origin xyz="0.15 0.0 0.03" rpy="0 0 0"/>
    <axis xyz="0 0 1"/>
  </joint>
  
  <!-- Camera/Sensor Module -->
  <link name="camera">
    <visual>
      <geometry>
        <box size="0.04 0.08 0.03"/>
      </geometry>
      <material name="DarkBlue">
        <color rgba="0.0 0.2 0.4 1.0"/>
      </material>
    </visual>
    <inertial>
      <mass value="0.05"/>
      <inertia ixx="0.00001" ixy="0.0" ixz="0.0" 
               iyy="0.00001" iyz="0.0" 
               izz="0.00001"/>
    </inertial>
  </link>
  
  <joint name="camera_joint" type="fixed">
    <parent link="base_link"/>
    <child link="camera"/>
    <origin xyz="0.15 0.0 -0.025" rpy="0 0.2 0"/>
  </joint>
  
  <!-- Gazebo materials and physics -->
  <gazebo reference="base_link">
    <material>Gazebo/Black</material>
    <turnGravityOff>true</turnGravityOff>
  </gazebo>
  
  <gazebo reference="arm_front_right">
    <material>Gazebo/Grey</material>
  </gazebo>
  
  <gazebo reference="arm_front_left">
    <material>Gazebo/Grey</material>
  </gazebo>
  
  <gazebo reference="arm_rear_right">
    <material>Gazebo/Grey</material>
  </gazebo>
  
  <gazebo reference="arm_rear_left">
    <material>Gazebo/Grey</material>
  </gazebo>
  
  <gazebo reference="rotor_front_right">
    <material>Gazebo/Red</material>
  </gazebo>
  
  <gazebo reference="rotor_front_left">
    <material>Gazebo/Blue</material>
  </gazebo>
  
  <gazebo reference="rotor_rear_right">
    <material>Gazebo/Blue</material>
  </gazebo>
  
  <gazebo reference="rotor_rear_left">
    <material>Gazebo/Red</material>
  </gazebo>
  
  <gazebo reference="camera">
    <material>Gazebo/DarkGrey</material>
  </gazebo>
  
</robot>
